<?xml version='1.0'?>
<robot xmlns:xacro="http://www.ros.org/wiki/xacro" name="panda">
  <!--xacro:macro name="panda_arm" params="arm_id:='panda' description_pkg:='summit_xl_description' connected_to:='' in_gazebo='false' xyz:='0 0 0' rpy:='0 0 0'"-->
  <xacro:macro name="panda_arm" params="arm_id:='panda' prefix load_gripper use_gazebo_control base_parent:=base_link pi_offset:=0.00001 description_pkg:='summit_xl_description' in_gazebo='true' connected_to:='robot_arm_link8' xyz:='0 0 0' rpy:='0 0 0' ">
  
    <!-- If using custom frame with ${connected_to} param, make sure 'world' frame exists in its TF tree -->
    <!--xacro:if value="${connected_to == ''}">
      <link name="world" />
      <xacro:property name="base_frame_name" value="world"/>
    </xacro:if>
    <xacro:unless value="${connected_to == ''}">
      <xacro:property name="base_frame_name" value="${connected_to}"/>
    </xacro:unless-->
    <!--joint name="${arm_id}_to_${base_frame_name}" type="fixed">
      <parent link="${base_frame_name}"/>
      <child link="${arm_id}_link0"/>
      <origin rpy="${rpy}" xyz="${xyz}"/>
      <xacro:unless value="${in_gazebo == 'false'}">
        <dynamics damping="1.0"/>
      </xacro:unless>
    </joint-->
    <link name="${base_parent}">
      <visual>
        <geometry>
          <mesh filename="package://interbotix_xsarm_descriptions/meshes/meshes/visual/link0.dae"/>
        </geometry>
      </visual>
      <collision>
        <geometry>
          <mesh filename="package://interbotix_xsarm_descriptions/meshes/meshes/collision/link0.stl"/>
        </geometry>
      </collision>
      <xacro:unless value="${in_gazebo == 'false'}">
        <inertial>
          <origin xyz="0 0 0" rpy="0 0 0"/>
          <mass value="3.06"/>
          <inertia ixx="0.3" ixy="0.0" ixz="0.0" iyy="0.3" iyz="0.0" izz="0.3"/>
        </inertial>
      </xacro:unless>
    </link>
    <link name="${prefix}link1">
      <visual>
        <geometry>
          <mesh filename="package://interbotix_xsarm_descriptions/meshes/meshes/visual/link1.dae"/>
        </geometry>
      </visual>
      <collision>
        <geometry>
          <mesh filename="package://interbotix_xsarm_descriptions/meshes/meshes/collision/link1.stl"/>
        </geometry>
      </collision>
      <inertial>
        <origin xyz="3.875e-03 2.081e-03 -0.1750" rpy="0 0 0"/>
        <mass value="4.970684"/>
        <inertia ixx="7.0337e-01" ixy="-1.3900e-04" ixz="6.7720e-03" iyy="7.0661e-01" iyz="1.9169e-02" izz="9.1170e-03"/>
      </inertial>
    </link>
    <joint name="${prefix}joint1" type="revolute">
      <safety_controller k_position="100.0" k_velocity="40.0" soft_lower_limit="-2.8973" soft_upper_limit="2.8973"/>
      <origin rpy="0 0 0" xyz="0 0 0.333"/>
      <parent link="${base_parent}"/>
      <child link="${prefix}link1"/>
      <axis xyz="0 0 1"/>
      <limit effort="87" lower="-2.8973" upper="2.8973" velocity="2.1750"/>
      <dynamics damping="10.0" friction="5.0"/>
    </joint>
    <link name="${prefix}link2">
      <visual>
        <geometry>
          <mesh filename="package://interbotix_xsarm_descriptions/meshes/meshes/visual/link2.dae"/>
        </geometry>
      </visual>
      <collision>
        <geometry>
          <mesh filename="package://interbotix_xsarm_descriptions/meshes/meshes/collision/link2.stl"/>
        </geometry>
      </collision>
      <inertial>
        <origin xyz="-3.141e-03 -2.872e-02 3.495e-03" rpy="0 0 0"/>
        <mass value="0.646926"/>
        <inertia ixx="7.9620e-03" ixy="-3.9250e-03" ixz="1.0254e-02" iyy="2.8110e-02" iyz="7.0400e-04" izz="2.5995e-02"/>
      </inertial>
    </link>
    <joint name="${prefix}joint2" type="revolute">
      <safety_controller k_position="100.0" k_velocity="40.0" soft_lower_limit="-1.7628" soft_upper_limit="1.7628"/>
      <origin rpy="${-pi/2} 0 0" xyz="0 0 0"/>
      <parent link="${prefix}link1"/>
      <child link="${prefix}link2"/>
      <axis xyz="0 0 1"/>
      <limit effort="87" lower="-1.7628" upper="1.7628" velocity="2.1750"/>
      <dynamics damping="5.0" friction="2.0"/>
    </joint>
    <link name="${prefix}link3">
      <visual>
        <geometry>
          <mesh filename="package://interbotix_xsarm_descriptions/meshes/meshes/visual/link3.dae"/>
        </geometry>
      </visual>
      <collision>
        <geometry>
          <mesh filename="package://interbotix_xsarm_descriptions/meshes/meshes/collision/link3.stl"/>
        </geometry>
      </collision>
      <inertial>
        <origin xyz="2.7518e-02 3.9252e-02 -6.6502e-02" rpy="0 0 0"/>
        <mass value="3.228604"/>
        <inertia ixx="3.7242e-02" ixy="-4.7610e-03" ixz="-1.1396e-02" iyy="3.6155e-02" iyz="-1.2805e-02" izz="1.0830e-02"/>
      </inertial>
    </link>
    <joint name="${prefix}joint3" type="revolute">
      <safety_controller k_position="100.0" k_velocity="40.0" soft_lower_limit="-2.8973" soft_upper_limit="2.8973"/>
      <origin rpy="${pi/2} 0 0" xyz="0 -0.316 0"/>
      <parent link="${prefix}link2"/>
      <child link="${prefix}link3"/>
      <axis xyz="0 0 1"/>
      <limit effort="87" lower="-2.8973" upper="2.8973" velocity="2.1750"/>
      <dynamics damping="5.0" friction="2.0"/>
    </joint>
    <link name="${prefix}link4">
      <visual>
        <geometry>
          <mesh filename="package://interbotix_xsarm_descriptions/meshes/meshes/visual/link4.dae"/>
        </geometry>
      </visual>
      <collision>
        <geometry>
          <mesh filename="package://interbotix_xsarm_descriptions/meshes/meshes/collision/link4.stl"/>
        </geometry>
      </collision>
      <inertial>
        <origin xyz="-5.317e-02 1.04419e-01 2.7454e-02" rpy="0 0 0"/>
        <mass value="3.587895"/>
        <inertia ixx="2.5853e-02" ixy="7.7960e-03" ixz="-1.3320e-03" iyy="1.9552e-02" iyz="8.6410e-03" izz="2.8323e-02"/>
      </inertial>
    </link>
    <joint name="${prefix}joint4" type="revolute">
      <safety_controller k_position="100.0" k_velocity="40.0" soft_lower_limit="-3.0718" soft_upper_limit="-0.0698"/>
      <origin rpy="${pi/2} 0 0" xyz="0.0825 0 0"/>
      <parent link="${prefix}link3"/>
      <child link="${prefix}link4"/>
      <axis xyz="0 0 1"/>
      <limit effort="87" lower="-3.0718" upper="-0.0698" velocity="2.1750"/>
      <dynamics damping="1.0" friction="0.5"/>
    </joint>
    <link name="${prefix}link5">
      <visual>
        <geometry>
          <mesh filename="package://interbotix_xsarm_descriptions/meshes/meshes/visual/link5.dae"/>
        </geometry>
      </visual>
      <collision>
        <geometry>
          <mesh filename="package://interbotix_xsarm_descriptions/meshes/meshes/collision/link5.stl"/>
        </geometry>
      </collision>
      <inertial>
        <origin xyz="-1.1953e-02 4.1065e-02 -3.8437e-02" rpy="0 0 0"/>
        <mass value="1.225946"/>
        <inertia ixx="3.5549e-02" ixy="-2.1170e-03" ixz="-4.0370e-03" iyy="2.9474e-02" iyz="2.2900e-04" izz="8.6270e-03"/>
      </inertial>
    </link>
    <joint name="${prefix}joint5" type="revolute">
      <safety_controller k_position="100.0" k_velocity="40.0" soft_lower_limit="-2.8973" soft_upper_limit="2.8973"/>
      <origin rpy="${-pi/2} 0 0" xyz="-0.0825 0.384 0"/>
      <parent link="${prefix}link4"/>
      <child link="${prefix}link5"/>
      <axis xyz="0 0 1"/>
      <limit effort="12" lower="-2.8973" upper="2.8973" velocity="2.6100"/>
      <dynamics damping="2.0" friction="1.0"/>
    </joint>
    <link name="${prefix}link6">
      <visual>
        <geometry>
          <mesh filename="package://interbotix_xsarm_descriptions/meshes/meshes/visual/link6.dae"/>
        </geometry>
      </visual>
      <collision>
        <geometry>
          <mesh filename="package://interbotix_xsarm_descriptions/meshes/meshes/collision/link6.stl"/>
        </geometry>
      </collision>
      <inertial>
        <origin xyz="6.0149e-02 -1.4117e-02 -1.0517e-02" rpy="0 0 0"/>
        <mass value="1.666555"/>
        <inertia ixx="1.9640e-03" ixy="1.0900e-04" ixz="-1.1580e-03" iyy="4.3540e-03" iyz="3.4100e-04" izz="5.4330e-03"/>
      </inertial>
    </link>
    <joint name="${prefix}joint6" type="revolute">
      <safety_controller k_position="100.0" k_velocity="40.0" soft_lower_limit="-0.0175" soft_upper_limit="3.7525"/>
      <origin rpy="${pi/2} 0 0" xyz="0 0 0"/>
      <parent link="${prefix}link5"/>
      <child link="${prefix}link6"/>
      <axis xyz="0 0 1"/>
      <limit effort="12" lower="-0.0175" upper="3.7525" velocity="2.6100"/>
      <dynamics damping="1.0" friction="0.5"/>
    </joint>
    <link name="${prefix}link7">
      <visual>
        <geometry>
          <mesh filename="package://interbotix_xsarm_descriptions/meshes/meshes/visual/link7.dae"/>
        </geometry>
      </visual>
      <collision>
        <geometry>
          <mesh filename="package://interbotix_xsarm_descriptions/meshes/meshes/collision/link7.stl"/>
        </geometry>
      </collision>
      <inertial>
        <origin xyz="1.0517e-02 -4.252e-03 6.1597e-02" rpy="0 0 0"/>
        <mass value="7.35522e-01"/>
        <inertia ixx="1.2516e-02" ixy="-4.2800e-04" ixz="-1.1960e-03" iyy="1.0027e-02" iyz="-7.4100e-04" izz="4.8150e-03"/>
      </inertial>
    </link>
    <joint name="${prefix}joint7" type="revolute">
      <safety_controller k_position="100.0" k_velocity="40.0" soft_lower_limit="-2.8973" soft_upper_limit="2.8973"/>
      <origin rpy="${pi/2} 0 0" xyz="0.088 0 0"/>
      <parent link="${prefix}link6"/>
      <child link="${prefix}link7"/>
      <axis xyz="0 0 1"/>
      <limit effort="12" lower="-2.8973" upper="2.8973" velocity="2.6100"/>
      <dynamics damping="1.0" friction="0.5"/>
    </joint>
    <link name="${prefix}link8">
      <inertial>
        <origin xyz="0 0 0" rpy="0 0 0"/>
        <mass value="0.0"/>
        <inertia ixx="0.001" ixy="0.0" ixz="0.0" iyy="0.001" iyz="0.0" izz="0.001"/>
      </inertial>
    </link>
    <joint name="${prefix}joint8" type="fixed">      
    <origin rpy="0 0 0" xyz="0 0 0.107"/>
      <parent link="${prefix}link7"/>
      <child link="${prefix}link8"/>
      <axis xyz="0 0 0"/>
    </joint>

<!-- Gripper -->
    <xacro:unless value="${connected_to == ''}">
      <joint name="${prefix}hand_joint" type="fixed">
        <parent link="${prefix}link8"/>
        <child link="${prefix}hand"/>
        <origin xyz="${xyz}" rpy="${rpy}"/>
      </joint>
    </xacro:unless>
    <link name="${prefix}hand">
      <visual>
        <geometry>
          <mesh filename="package://interbotix_xsarm_descriptions/meshes/meshes/visual/hand.dae"/>
        </geometry>
      </visual>
      <collision>
        <geometry>
          <mesh filename="package://interbotix_xsarm_descriptions/meshes/meshes/collision/hand.stl"/>
        </geometry>
      </collision>
      <inertial>
        <origin rpy="0 0 0" xyz="0 0.0015244 0.0275912"/>
        <mass value="0.73"/>
        <inertia ixx="0.00278560230025" ixy="0.0" ixz="0.0" iyy="0.000400033405336" iyz="0.0" izz="0.00256378041832"/>
      </inertial>
    </link>
    <link name="${prefix}leftfinger">
      <visual>
        <geometry>
          <mesh filename="package://interbotix_xsarm_descriptions/meshes/meshes/visual/finger.dae"/>
        </geometry>
      </visual>
      <collision>
        <geometry>
          <mesh filename="package://interbotix_xsarm_descriptions/meshes/meshes/collision/finger.stl"/>
        </geometry>
      </collision>
      <inertial>
        <origin rpy="0 0 0" xyz="0 0.0145644 0.0227941"/>
        <mass value="0.1"/>
        <inertia ixx="3.01220925051e-05" ixy="0.0" ixz="0.0" iyy="2.95873808038e-05" iyz="0.0" izz="6.95125211657e-06"/>
      </inertial>
    </link>
    <link name="${prefix}rightfinger">
      <visual>
        <origin xyz="0 0 0" rpy="0 0 ${pi}"/>
        <geometry>
          <mesh filename="package://interbotix_xsarm_descriptions/meshes/meshes/visual/finger.dae"/>
        </geometry>
      </visual>
      <collision>
        <origin xyz="0 0 0" rpy="0 0 ${pi}"/>
        <geometry>
          <mesh filename="package://interbotix_xsarm_descriptions/meshes/meshes/collision/finger.stl"/>
        </geometry>
      </collision>
      <inertial>
        <origin rpy="0 0 3.141592653589793" xyz="0 -0.0145644 0.0227941"/>
        <mass value="0.1"/>
        <inertia ixx="3.01220925051e-05" ixy="0.0" ixz="0.0" iyy="2.95873808038e-05" iyz="0.0" izz="6.95125211657e-06"/>
      </inertial>
    </link>
    <joint name="${prefix}finger_joint1" type="prismatic">
      <parent link="${prefix}hand"/>
      <child link="${prefix}leftfinger"/>
      <origin xyz="0 0 0.0584" rpy="0 0 0"/>
      <axis xyz="0 1 0"/>
      <limit effort="20" lower="0.0" upper="0.04" velocity="0.2"/>
      <dynamics damping="500.0" friction="0.0"/>
    </joint>
    <joint name="${prefix}finger_joint2" type="prismatic">
      <parent link="${prefix}hand"/>
      <child link="${prefix}rightfinger"/>
      <origin xyz="0 0 0.0584" rpy="0 0 0"/>
      <axis xyz="0 -1 0"/>
      <limit effort="20" lower="0.0" upper="0.04" velocity="0.2"/>
      <dynamics damping="500.0" friction="0.0"/>
      
    </joint>

    <!-- Load Gazebo lib and set the robot namespace -->
        
            <!--gazebo>
                <plugin name="gazebo_ros_control" filename="libgazebo_ros_control.so">
                    <robotNamespace>/panda</robotNamespace>
                    <robotSimType>gazebo_ros_control/DefaultRobotHWSim</robotSimType>
                    <legacyModeNS>true</legacyModeNS>
                </plugin>
            </gazebo-->
        
     <transmission name="${prefix}tran_1">
            <type>transmission_interface/SimpleTransmission</type>
            <joint name="${prefix}joint1">
                <hardwareInterface>hardware_interface/PositionJointInterface</hardwareInterface>
            </joint>
            <actuator name="${prefix}motor_1">
                <hardwareInterface>hardware_interface/PositionJointInterface</hardwareInterface>
                <mechanicalReduction>1</mechanicalReduction>
            </actuator>
        </transmission>

        <transmission name="${prefix}tran_2">
            <type>transmission_interface/SimpleTransmission</type>
            <joint name="${prefix}joint2">
                <hardwareInterface>hardware_interface/PositionJointInterface</hardwareInterface>
            </joint>
            <actuator name="${prefix}motor_2">
                <hardwareInterface>hardware_interface/PositionJointInterface</hardwareInterface>
                <mechanicalReduction>1</mechanicalReduction>
            </actuator>
        </transmission>

        <transmission name="${prefix}tran_3">
            <type>transmission_interface/SimpleTransmission</type>
            <joint name="${prefix}joint3">
                <hardwareInterface>hardware_interface/PositionJointInterface</hardwareInterface>
            </joint>
            <actuator name="${prefix}motor_3">
                <hardwareInterface>hardware_interface/PositionJointInterface</hardwareInterface>
                <mechanicalReduction>1</mechanicalReduction>
            </actuator>
        </transmission>

        <transmission name="${prefix}tran_4">
            <type>transmission_interface/SimpleTransmission</type>
            <joint name="${prefix}joint4">
                <hardwareInterface>hardware_interface/PositionJointInterface</hardwareInterface>
            </joint>
            <actuator name="${prefix}motor_4">
                <hardwareInterface>hardware_interface/PositionJointInterface</hardwareInterface>
                <mechanicalReduction>1</mechanicalReduction>
            </actuator>
        </transmission>

        <transmission name="${prefix}tran_5">
            <type>transmission_interface/SimpleTransmission</type>
            <joint name="${prefix}joint5">
                <hardwareInterface>hardware_interface/PositionJointInterface</hardwareInterface>
            </joint>
            <actuator name="${prefix}motor_5">
                <hardwareInterface>hardware_interface/PositionJointInterface</hardwareInterface>
                <mechanicalReduction>1</mechanicalReduction>
            </actuator>
        </transmission>

        <transmission name="${prefix}tran_6">
            <type>transmission_interface/SimpleTransmission</type>
            <joint name="${prefix}joint6">
                <hardwareInterface>hardware_interface/PositionJointInterface</hardwareInterface>
            </joint>
            <actuator name="${prefix}motor_6">
                <hardwareInterface>hardware_interface/PositionJointInterface</hardwareInterface>
                <mechanicalReduction>1</mechanicalReduction>
            </actuator>
        </transmission>

        <transmission name="${prefix}tran_7">
            <type>transmission_interface/SimpleTransmission</type>
            <joint name="${prefix}joint7">
                <hardwareInterface>hardware_interface/PositionJointInterface</hardwareInterface>
            </joint>
            <actuator name="${prefix}motor_7">
                <hardwareInterface>hardware_interface/PositionJointInterface</hardwareInterface>
                <mechanicalReduction>1</mechanicalReduction>
            </actuator>
        </transmission>

        <xacro:if value="${load_gripper}">
            <transmission name="${prefix}leftfinger">
                <type>transmission_interface/SimpleTransmission</type>
                <joint name="${prefix}finger_joint1">
                    <hardwareInterface>hardware_interface/PositionJointInterface</hardwareInterface>
                </joint>
                <actuator name="${prefix}finger_joint1">
                    <hardwareInterface>hardware_interface/PositionJointInterface</hardwareInterface>
                    <mechanicalReduction>1</mechanicalReduction>
                </actuator>
            </transmission>

            <transmission name="${prefix}rightfinger">
                <type>transmission_interface/SimpleTransmission</type>
                <joint name="${prefix}finger_joint2">
                    <hardwareInterface>hardware_interface/PositionJointInterface</hardwareInterface>
                </joint>
                <actuator name="${prefix}finger_joint2">
                    <hardwareInterface>hardware_interface/PositionJointInterface</hardwareInterface>
                    <mechanicalReduction>1</mechanicalReduction>
                </actuator>
            </transmission>
        </xacro:if>
        
        <gazebo reference="${base_parent}">
        <implicitSpringDamper>1</implicitSpringDamper>
        <provideFeedback>true</provideFeedback>
      </gazebo>
      <gazebo reference="${prefix}joint7">
        <implicitSpringDamper>1</implicitSpringDamper>
        <provideFeedback>true</provideFeedback>
      </gazebo>
      <gazebo reference="${prefix}joint1">
        <implicitSpringDamper>1</implicitSpringDamper>
        <provideFeedback>true</provideFeedback>
      </gazebo>
      <gazebo reference="${prefix}joint2">
        <implicitSpringDamper>1</implicitSpringDamper>
        <provideFeedback>true</provideFeedback>
      </gazebo>
      <gazebo reference="${prefix}joint3">
        <implicitSpringDamper>1</implicitSpringDamper>
        <provideFeedback>true</provideFeedback>
      </gazebo>
      <gazebo reference="${prefix}joint4">
        <implicitSpringDamper>1</implicitSpringDamper>
        <provideFeedback>true</provideFeedback>
      </gazebo>
      <gazebo reference="${prefix}joint5">
        <implicitSpringDamper>1</implicitSpringDamper>
        <provideFeedback>true</provideFeedback>
      </gazebo>
      <gazebo reference="${prefix}joint6">
        <implicitSpringDamper>1</implicitSpringDamper>
        <provideFeedback>true</provideFeedback>
      </gazebo>
      <xacro:if value="${load_gripper}">
          <gazebo reference="${prefix}finger_joint1">
            <implicitSpringDamper>1</implicitSpringDamper>
            <provideFeedback>true</provideFeedback>
          </gazebo>
          <gazebo reference="${prefix}finger_joint2">
            <implicitSpringDamper>1</implicitSpringDamper>
            <provideFeedback>true</provideFeedback>
          </gazebo>
      </xacro:if>

    <!-- Adding FT sensor at wrist. This is not present in real robot and is used only for computing end-point effort directly, unlike in the real robot where it is estimated from the joint efforts. -->
    <gazebo reference="${prefix}joint7">
      <disableFixedJointLumping>true</disableFixedJointLumping>
      <sensor name="${prefix}joint7_force_torque" type="force_torque">
        <always_on>true</always_on>
        <visualize>false</visualize>
        <force_torque>
          <frame>sensor</frame>
          <measure_direction>child_to_parent</measure_direction>
        </force_torque>
      </sensor>
    </gazebo>
    <gazebo>
      <plugin name="ft_sensor" filename="libgazebo_ros_ft_sensor.so">
        <updateRate>30.0</updateRate>
        <topicName>/gazebo/robot/wrist/ft</topicName>
        <jointName>${prefix}joint7</jointName>
      </plugin>
    </gazebo>

    <!-- Configure self collision properties per link -->
    <!-- The gripper fingers do not have this flag otherwise the gripper would not be allowed to close correctly -->
    <gazebo reference="${prefix}link1">
      <selfCollide>true</selfCollide>
    </gazebo>

    <gazebo reference="${prefix}link2">
      <selfCollide>true</selfCollide>
    </gazebo>

    <gazebo reference="${prefix}link3">
      <selfCollide>true</selfCollide>
    </gazebo>

    <gazebo reference="${prefix}link4">
      <selfCollide>true</selfCollide>
    </gazebo>

    <gazebo reference="${prefix}link5">
      <selfCollide>true</selfCollide>
    </gazebo>

    <gazebo reference="${prefix}link6">
      <selfCollide>true</selfCollide>
    </gazebo>

    <gazebo reference="${prefix}link7">
      <selfCollide>true</selfCollide>
    </gazebo>
  
    <!-- Collision sensors on all links. This is not present on the real robot, it is used only in simulation to detect collisions. -->
    <!-- Link 0 is omitted because it is always in contact with the ground  -->
    <gazebo reference="${prefix}link1">
      <sensor name='${prefix}link1_contact' type='contact'>
        <update_rate> 50 </update_rate>
        <always_on>true</always_on>
          <contact>
              <collision>${prefix}link1_collision</collision>
          </contact>
          <plugin name="link1_bumper" filename="libgazebo_ros_bumper.so">
            <bumperTopicName>${prefix}link1_collision</bumperTopicName>
            <frameName>${prefix}link1</frameName>
          </plugin>
      </sensor>
    </gazebo>

    <gazebo reference="${prefix}link2">
      <sensor name='${prefix}link2_contact' type='contact'>
        <update_rate> 50 </update_rate>
        <always_on>true</always_on>
          <contact>
              <collision>${prefix}link2_collision</collision>
          </contact>
          <plugin name="link2_bumper" filename="libgazebo_ros_bumper.so">
            <bumperTopicName>${prefix}link2_collision</bumperTopicName>
            <frameName>${prefix}link2</frameName>
          </plugin>
      </sensor>
    </gazebo>

    <gazebo reference="${prefix}link3">
      <sensor name='${prefix}link3_contact' type='contact'>
        <update_rate> 50 </update_rate>
        <always_on>true</always_on>
          <contact>
              <collision>${prefix}link3_collision</collision>
          </contact>
          <plugin name="link3_bumper" filename="libgazebo_ros_bumper.so">
            <bumperTopicName>${prefix}link3_collision</bumperTopicName>
            <frameName>${prefix}link3</frameName>
          </plugin>
      </sensor>
    </gazebo>

    <gazebo reference="${prefix}link4">
      <sensor name='${prefix}link4_contact' type='contact'>
        <update_rate> 50 </update_rate>
        <always_on>true</always_on>
          <contact>
              <collision>${prefix}link4_collision</collision>
          </contact>
          <plugin name="link4_bumper" filename="libgazebo_ros_bumper.so">
            <bumperTopicName>${prefix}link4_collision</bumperTopicName>
            <frameName>${prefix}link4</frameName>
          </plugin>
      </sensor>
    </gazebo>

    <gazebo reference="${prefix}link5">
      <sensor name='${prefix}link5_contact' type='contact'>
        <update_rate> 50 </update_rate>
        <always_on>true</always_on>
          <contact>
              <collision>${prefix}link5_collision</collision>
          </contact>
          <plugin name="link5_bumper" filename="libgazebo_ros_bumper.so">
            <bumperTopicName>${prefix}link5_collision</bumperTopicName>
            <frameName>${prefix}link5</frameName>
          </plugin>
      </sensor>
    </gazebo>

    <gazebo reference="${prefix}link6">
      <sensor name='${prefix}link6_contact' type='contact'>
        <update_rate> 50 </update_rate>
        <always_on>true</always_on>
          <contact>
              <collision>${prefix}link6_collision</collision>
          </contact>
          <plugin name="link6_bumper" filename="libgazebo_ros_bumper.so">
            <bumperTopicName>${prefix}link6_collision</bumperTopicName>
            <frameName>${prefix}link6</frameName>
          </plugin>
      </sensor>
    </gazebo> 

    <gazebo reference="${prefix}link7">
      <sensor name='${prefix}link7_contact' type='contact'>
        <update_rate> 50 </update_rate>
        <always_on>true</always_on>
          <contact>
              <collision>${prefix}link7_collision</collision>
          </contact>
          <plugin name="link7_bumper" filename="libgazebo_ros_bumper.so">
            <bumperTopicName>${prefix}link7_collision</bumperTopicName>
            <frameName>${prefix}link7</frameName>
          </plugin>
      </sensor>
    </gazebo>

    <gazebo reference="${prefix}leftfinger">
      <sensor name='${prefix}leftfinger_contact' type='contact'>
        <update_rate> 50 </update_rate>
        <always_on>true</always_on>
          <contact>
              <collision>${prefix}leftfinger_collision</collision>
          </contact>
          <plugin name="leftfinger_bumper" filename="libgazebo_ros_bumper.so">
            <bumperTopicName>${prefix}leftfinger_collision</bumperTopicName>
            <frameName>${prefix}leftfinger</frameName>
          </plugin>
      </sensor>
    </gazebo>

    <gazebo reference="${prefix}rightfinger">
      <sensor name='${prefix}rightfinger_contact' type='contact'>
        <update_rate> 50 </update_rate>
        <always_on>true</always_on>
          <contact>
              <collision>${prefix}rightfinger_collision</collision>
          </contact>
          <plugin name="rightfinger_bumper" filename="libgazebo_ros_bumper.so">
            <bumperTopicName>${prefix}rightfinger_collision</bumperTopicName>
            <frameName>${prefix}rightfinger</frameName>
          </plugin>
      </sensor>
    </gazebo>

  </xacro:macro>
</robot>
